Workbook

Sheet Backlog
A1: ID | B1: Parent | C1: Task | D1: Mod | E1: System | F1: Type | G1: Priority | H1: Status | I1: Effort | J1: Original section | K1: Notes
A2: T-001 | C2: Operation to gather herbs automatically | D2: GBO3 | E2: Operations | F2: Feature | G2: P3 | H2: Open | J2: Unsorted
A3: T-002 | C3: Review no-stock aim penalty: no-stock SMGs struggle to out-aim pistols | D3: GBO3 | E3: Weapons | F3: Balance | G3: P2 | H3: Open | J3: Unsorted
A4: T-003 | C4: Overwatch against doors | D4: AI Overhaul | E4: AI Behavior | F4: Feature | G4: P2 | H4: Open | J4: AI new stuff
A5: T-004 | C5: Enemy leaving view should not reveal its position to the player | D5: AI Overhaul | E5: Visibility | F5: Feature | G5: P2 | H5: Open | J5: AI new stuff | K5: Mod assignment uncertain (could be GBO3)
A6: T-005 | C6: AP check so autofire is selectable when merc can fire 2 bullets | D6: GBO3 | E6: Fire Modes | F6: Feature | G6: P2 | H6: Done | J6: Fire modes
A7: T-006 | C7: Maybe change HK receiver effect for clarity | D7: GBO3 | E7: Components | F7: UX | G7: P3 | H7: Open | J7: Fire modes
A8: T-007 | C8: Selective burst on HK21 and other MGs that have it | D8: GBO3 | E8: Fire Modes | F8: Feature | G8: P2 | H8: Open | J8: Fire modes
A9: T-008 | C9: MG description hints not showing ROF | D9: GBO3 | E9: UI & Descriptions | F9: Bug | G9: P2 | H9: Done | J9: Fire modes
A10: T-009 | C10: Recoil booster | D10: GBO3 | E10: Components | F10: Feature | G10: P2 | H10: Done | J10: Fire modes
A11: T-010 | C11: Adjust MG 58 RPM | D11: GBO3 | E11: Fire Modes | F11: Balance | G11: P2 | H11: Done | J11: Fire modes
A12: T-011 | C12: Investigate burst fire AP or RPM | D12: GBO3 | E12: Fire Modes | F12: Investigation | G12: P2 | H12: Done | J12: Fire modes
A13: T-012 | C13: Solve the AKSU reliability dilemma | D13: GBO3 | E13: Weapons | F13: Balance | G13: P2 | H13: Open | J13: Fire modes
A14: T-013 | C14: Better crit scaling for selective burst | D14: GBO3 | E14: Fire Modes | F14: Balance | G14: P2 | H14: Done | J14: Fire modes
A15: T-014 | C15: Psycho trait | D15: GBO3 | E15: Perks & Traits | F15: Feature | G15: P2 | H15: Open | J15: Fire modes | K15: Scope not specified in original
A16: T-015 | C16: MG higher base AP cost? | D16: GBO3 | E16: AP Economy | F16: Balance | G16: P3 | H16: Proposal | J16: Fire modes
A17: T-016 | C17: Mouseover showing how many attacks fit at a position (stance, aim) given fractional AP | D17: GBO3 | E17: UI & Descriptions | F17: UX | G17: P2 | H17: Open | J17: UI
A18: T-017 | C18: Burst weapon AP shows a stale number | D18: GBO3 | E18: UI & Descriptions | F18: Bug | G18: P1 | H18: Open | J18: UI
A19: T-018 | C19: Show recoil delta on actions | D19: GBO3 | E19: UI & Descriptions | F19: UX | G19: P2 | H19: Open | J19: UI
A20: T-019 | C20: Caliber/ammo params in their own section (remove crit damage and base chance from hints) | D20: GBO3 | E20: UI & Descriptions | F20: UX | G20: P2 | H20: Done | J20: UI
A21: T-020 | C21: Scale aim in hints by merc and handgun status | D21: GBO3 | E21: UI & Descriptions | F21: UX | G21: P2 | H21: Done | J21: UI
A22: T-021 | C22: Pellet count in caliber section | D22: GBO3 | E22: UI & Descriptions | F22: UX | G22: P3 | H22: Done | J22: UI
A23: T-022 | C23: Further details include AP to swap and AP to reload | D23: GBO3 | E23: UI & Descriptions | F23: UX | G23: P3 | H23: Done | J23: UI
A24: T-023 | C24: Noise shown even when no ammo loaded | D24: GBO3 | E24: UI & Descriptions | F24: Bug | G24: P3 | H24: Done | J24: UI
A25: T-024 | C25: Bobby Ray's showing old crit scaling | D25: GBO3 | E25: UI & Descriptions | F25: Bug | G25: P2 | H25: Done | J25: UI
A26: T-025 | C26: Unified component handling with ancestor/CTH mode | D26: GBO3 | E26: Components | F26: Refactor | G26: P1 | H26: Done | J26: Housekeeping
A27: T-026 | B27: T-025 | C27: ↳ Fix/unify with aCTH logic | D27: GBO3 | E27: Components | F27: Refactor | G27: P1 | H27: Done | J27: Housekeeping
A28: T-027 | B28: T-025 | C28: ↳ Verify whether the patch called from ToG is redundant | D28: GBO3 | E28: Compatibility | F28: Investigation | G28: P2 | H28: Done | J28: Housekeeping | K28: Not redundant: visual changes and foldable stock foldability
A29: T-028 | C29: Remove unused calibers from Bobby Ray's list | D29: GBO3 | E29: Loot & Economy | F29: Content | G29: P3 | H29: Done | J29: Housekeeping
A30: T-029 | C30: Check unjam skill mechanic; if flat, turn into a skill check | D30: GBO3 | E30: Weapons | F30: Balance | G30: P2 | H30: Open | J30: General
A31: T-030 | C31: Heavy rain aim penalty triggering indoors? | D31: GBO3 | E31: Accuracy | F31: Investigation | G31: P2 | H31: Open | J31: General
A32: T-031 | C32: Cumbersome stance AP not on new scale (description hints, display only) | D32: GBO3 | E32: AP Economy | F32: Bug | G32: P2 | H32: Done | J32: New AP scale
A33: T-032 | C33: Gas mask AP reduction not on new scale | D33: GBO3 | E33: AP Economy | F33: Bug | G33: P1 | H33: Open | J33: New AP scale
A34: T-033 | C34: AP calc can yield less than a 10 step | D34: GBO3 | E34: AP Economy | F34: Refactor | G34: P3 | H34: Done | J34: New AP scale
A35: T-034 | C35: Morale effects using old AP scale | D35: GBO3 | E35: AP Economy | F35: Bug | G35: P1 | H35: Done | J35: New AP scale
A36: T-035 | C36: Shipments: got a tier 3 MG after 2 fights | D36: GBO3 | E36: Loot & Economy | F36: Balance | G36: P2 | H36: Done | J36: Components
A37: T-036 | C37: Investigate and balance tier unlocking | D37: GBO3 | E37: Components | F37: Balance | G37: P2 | H37: Open | J37: Attachments
A38: T-037 | C38: Possibly rescale parts gained | D38: GBO3 | E38: Loot & Economy | F38: Balance | G38: P3 | H38: Open | J38: Attachments
A39: T-038 | C39: CUAE handling of attachments | D39: GBO3 | E39: Compatibility | F39: Feature | G39: P2 | H39: Open | J39: Attachments
A40: T-039 | C40: Spreadsheet for attachment costs | D40: GBO3 | E40: Components | F40: Tooling/Docs | G40: P3 | H40: Open | J40: Attachments
...

Sheet Summary
A1: By priority
A2: Priority | B2: Open | C2: Proposal | D2: Needs testing | E2: Disabled | F2: Done | G2: Total | H2: Open %
A3: P1 | B3: =COUNTIFS(Backlog!$G$2:$G$378,$A3,Backlog!$H$2:$H$378,"Open") | C3: =COUNTIFS(Backlog!$G$2:$G$378,$A3,Backlog!$H$2:$H$378,"Proposal") | D3: =COUNTIFS(Backlog!$G$2:$G$378,$A3,Backlog!$H$2:$H$378,"Needs testing") | E3: =COUNTIFS(Backlog!$G$2:$G$378,$A3,Backlog!$H$2:$H$378,"Disabled") | F3: =COUNTIFS(Backlog!$G$2:$G$378,$A3,Backlog!$H$2:$H$378,"Done") | G3: =SUM(B3:F3) | H3: =IF(G3=0,0,(B3+C3+D3)/G3)
A4: P2 | B4: =COUNTIFS(Backlog!$G$2:$G$378,$A4,Backlog!$H$2:$H$378,"Open") | C4: =COUNTIFS(Backlog!$G$2:$G$378,$A4,Backlog!$H$2:$H$378,"Proposal") | D4: =COUNTIFS(Backlog!$G$2:$G$378,$A4,Backlog!$H$2:$H$378,"Needs testing") | E4: =COUNTIFS(Backlog!$G$2:$G$378,$A4,Backlog!$H$2:$H$378,"Disabled") | F4: =COUNTIFS(Backlog!$G$2:$G$378,$A4,Backlog!$H$2:$H$378,"Done") | G4: =SUM(B4:F4) | H4: =IF(G4=0,0,(B4+C4+D4)/G4)
A5: P3 | B5: =COUNTIFS(Backlog!$G$2:$G$378,$A5,Backlog!$H$2:$H$378,"Open") | C5: =COUNTIFS(Backlog!$G$2:$G$378,$A5,Backlog!$H$2:$H$378,"Proposal") | D5: =COUNTIFS(Backlog!$G$2:$G$378,$A5,Backlog!$H$2:$H$378,"Needs testing") | E5: =COUNTIFS(Backlog!$G$2:$G$378,$A5,Backlog!$H$2:$H$378,"Disabled") | F5: =COUNTIFS(Backlog!$G$2:$G$378,$A5,Backlog!$H$2:$H$378,"Done") | G5: =SUM(B5:F5) | H5: =IF(G5=0,0,(B5+C5+D5)/G5)
A6: P4 | B6: =COUNTIFS(Backlog!$G$2:$G$378,$A6,Backlog!$H$2:$H$378,"Open") | C6: =COUNTIFS(Backlog!$G$2:$G$378,$A6,Backlog!$H$2:$H$378,"Proposal") | D6: =COUNTIFS(Backlog!$G$2:$G$378,$A6,Backlog!$H$2:$H$378,"Needs testing") | E6: =COUNTIFS(Backlog!$G$2:$G$378,$A6,Backlog!$H$2:$H$378,"Disabled") | F6: =COUNTIFS(Backlog!$G$2:$G$378,$A6,Backlog!$H$2:$H$378,"Done") | G6: =SUM(B6:F6) | H6: =IF(G6=0,0,(B6+C6+D6)/G6)
A7: Total | B7: =SUM(B3:B6) | C7: =SUM(C3:C6) | D7: =SUM(D3:D6) | E7: =SUM(E3:E6) | F7: =SUM(F3:F6) | G7: =SUM(G3:G6) | H7: =IF(G7=0,0,(B7+C7+D7)/G7)
A9: By type
A10: Type | B10: Open | C10: Proposal | D10: Needs testing | E10: Disabled | F10: Done | G10: Total | H10: Open %
A11: Bug | B11: =COUNTIFS(Backlog!$F$2:$F$378,$A11,Backlog!$H$2:$H$378,"Open") | C11: =COUNTIFS(Backlog!$F$2:$F$378,$A11,Backlog!$H$2:$H$378,"Proposal") | D11: =COUNTIFS(Backlog!$F$2:$F$378,$A11,Backlog!$H$2:$H$378,"Needs testing") | E11: =COUNTIFS(Backlog!$F$2:$F$378,$A11,Backlog!$H$2:$H$378,"Disabled") | F11: =COUNTIFS(Backlog!$F$2:$F$378,$A11,Backlog!$H$2:$H$378,"Done") | G11: =SUM(B11:F11) | H11: =IF(G11=0,0,(B11+C11+D11)/G11)
A12: Feature | B12: =COUNTIFS(Backlog!$F$2:$F$378,$A12,Backlog!$H$2:$H$378,"Open") | C12: =COUNTIFS(Backlog!$F$2:$F$378,$A12,Backlog!$H$2:$H$378,"Proposal") | D12: =COUNTIFS(Backlog!$F$2:$F$378,$A12,Backlog!$H$2:$H$378,"Needs testing") | E12: =COUNTIFS(Backlog!$F$2:$F$378,$A12,Backlog!$H$2:$H$378,"Disabled") | F12: =COUNTIFS(Backlog!$F$2:$F$378,$A12,Backlog!$H$2:$H$378,"Done") | G12: =SUM(B12:F12) | H12: =IF(G12=0,0,(B12+C12+D12)/G12)
A13: Balance | B13: =COUNTIFS(Backlog!$F$2:$F$378,$A13,Backlog!$H$2:$H$378,"Open") | C13: =COUNTIFS(Backlog!$F$2:$F$378,$A13,Backlog!$H$2:$H$378,"Proposal") | D13: =COUNTIFS(Backlog!$F$2:$F$378,$A13,Backlog!$H$2:$H$378,"Needs testing") | E13: =COUNTIFS(Backlog!$F$2:$F$378,$A13,Backlog!$H$2:$H$378,"Disabled") | F13: =COUNTIFS(Backlog!$F$2:$F$378,$A13,Backlog!$H$2:$H$378,"Done") | G13: =SUM(B13:F13) | H13: =IF(G13=0,0,(B13+C13+D13)/G13)
A14: UX | B14: =COUNTIFS(Backlog!$F$2:$F$378,$A14,Backlog!$H$2:$H$378,"Open") | C14: =COUNTIFS(Backlog!$F$2:$F$378,$A14,Backlog!$H$2:$H$378,"Proposal") | D14: =COUNTIFS(Backlog!$F$2:$F$378,$A14,Backlog!$H$2:$H$378,"Needs testing") | E14: =COUNTIFS(Backlog!$F$2:$F$378,$A14,Backlog!$H$2:$H$378,"Disabled") | F14: =COUNTIFS(Backlog!$F$2:$F$378,$A14,Backlog!$H$2:$H$378,"Done") | G14: =SUM(B14:F14) | H14: =IF(G14=0,0,(B14+C14+D14)/G14)
A15: Text | B15: =COUNTIFS(Backlog!$F$2:$F$378,$A15,Backlog!$H$2:$H$378,"Open") | C15: =COUNTIFS(Backlog!$F$2:$F$378,$A15,Backlog!$H$2:$H$378,"Proposal") | D15: =COUNTIFS(Backlog!$F$2:$F$378,$A15,Backlog!$H$2:$H$378,"Needs testing") | E15: =COUNTIFS(Backlog!$F$2:$F$378,$A15,Backlog!$H$2:$H$378,"Disabled") | F15: =COUNTIFS(Backlog!$F$2:$F$378,$A15,Backlog!$H$2:$H$378,"Done") | G15: =SUM(B15:F15) | H15: =IF(G15=0,0,(B15+C15+D15)/G15)
A16: Investigation | B16: =COUNTIFS(Backlog!$F$2:$F$378,$A16,Backlog!$H$2:$H$378,"Open") | C16: =COUNTIFS(Backlog!$F$2:$F$378,$A16,Backlog!$H$2:$H$378,"Proposal") | D16: =COUNTIFS(Backlog!$F$2:$F$378,$A16,Backlog!$H$2:$H$378,"Needs testing") | E16: =COUNTIFS(Backlog!$F$2:$F$378,$A16,Backlog!$H$2:$H$378,"Disabled") | F16: =COUNTIFS(Backlog!$F$2:$F$378,$A16,Backlog!$H$2:$H$378,"Done") | G16: =SUM(B16:F16) | H16: =IF(G16=0,0,(B16+C16+D16)/G16)
A17: QA | B17: =COUNTIFS(Backlog!$F$2:$F$378,$A17,Backlog!$H$2:$H$378,"Open") | C17: =COUNTIFS(Backlog!$F$2:$F$378,$A17,Backlog!$H$2:$H$378,"Proposal") | D17: =COUNTIFS(Backlog!$F$2:$F$378,$A17,Backlog!$H$2:$H$378,"Needs testing") | E17: =COUNTIFS(Backlog!$F$2:$F$378,$A17,Backlog!$H$2:$H$378,"Disabled") | F17: =COUNTIFS(Backlog!$F$2:$F$378,$A17,Backlog!$H$2:$H$378,"Done") | G17: =SUM(B17:F17) | H17: =IF(G17=0,0,(B17+C17+D17)/G17)
A18: Refactor | B18: =COUNTIFS(Backlog!$F$2:$F$378,$A18,Backlog!$H$2:$H$378,"Open") | C18: =COUNTIFS(Backlog!$F$2:$F$378,$A18,Backlog!$H$2:$H$378,"Proposal") | D18: =COUNTIFS(Backlog!$F$2:$F$378,$A18,Backlog!$H$2:$H$378,"Needs testing") | E18: =COUNTIFS(Backlog!$F$2:$F$378,$A18,Backlog!$H$2:$H$378,"Disabled") | F18: =COUNTIFS(Backlog!$F$2:$F$378,$A18,Backlog!$H$2:$H$378,"Done") | G18: =SUM(B18:F18) | H18: =IF(G18=0,0,(B18+C18+D18)/G18)
A19: Content | B19: =COUNTIFS(Backlog!$F$2:$F$378,$A19,Backlog!$H$2:$H$378,"Open") | C19: =COUNTIFS(Backlog!$F$2:$F$378,$A19,Backlog!$H$2:$H$378,"Proposal") | D19: =COUNTIFS(Backlog!$F$2:$F$378,$A19,Backlog!$H$2:$H$378,"Needs testing") | E19: =COUNTIFS(Backlog!$F$2:$F$378,$A19,Backlog!$H$2:$H$378,"Disabled") | F19: =COUNTIFS(Backlog!$F$2:$F$378,$A19,Backlog!$H$2:$H$378,"Done") | G19: =SUM(B19:F19) | H19: =IF(G19=0,0,(B19+C19+D19)/G19)
A20: Art/Content | B20: =COUNTIFS(Backlog!$F$2:$F$378,$A20,Backlog!$H$2:$H$378,"Open") | C20: =COUNTIFS(Backlog!$F$2:$F$378,$A20,Backlog!$H$2:$H$378,"Proposal") | D20: =COUNTIFS(Backlog!$F$2:$F$378,$A20,Backlog!$H$2:$H$378,"Needs testing") | E20: =COUNTIFS(Backlog!$F$2:$F$378,$A20,Backlog!$H$2:$H$378,"Disabled") | F20: =COUNTIFS(Backlog!$F$2:$F$378,$A20,Backlog!$H$2:$H$378,"Done") | G20: =SUM(B20:F20) | H20: =IF(G20=0,0,(B20+C20+D20)/G20)
A21: Tooling/Docs | B21: =COUNTIFS(Backlog!$F$2:$F$378,$A21,Backlog!$H$2:$H$378,"Open") | C21: =COUNTIFS(Backlog!$F$2:$F$378,$A21,Backlog!$H$2:$H$378,"Proposal") | D21: =COUNTIFS(Backlog!$F$2:$F$378,$A21,Backlog!$H$2:$H$378,"Needs testing") | E21: =COUNTIFS(Backlog!$F$2:$F$378,$A21,Backlog!$H$2:$H$378,"Disabled") | F21: =COUNTIFS(Backlog!$F$2:$F$378,$A21,Backlog!$H$2:$H$378,"Done") | G21: =SUM(B21:F21) | H21: =IF(G21=0,0,(B21+C21+D21)/G21)
A22: Total | B22: =SUM(B11:B21) | C22: =SUM(C11:C21) | D22: =SUM(D11:D21) | E22: =SUM(E11:E21) | F22: =SUM(F11:F21) | G22: =SUM(G11:G21) | H22: =IF(G22=0,0,(B22+C22+D22)/G22)
A24: By mod
A25: Mod | B25: Open | C25: Proposal | D25: Needs testing | E25: Disabled | F25: Done | G25: Total | H25: Open %
A26: GBO3 | B26: =COUNTIFS(Backlog!$D$2:$D$378,$A26,Backlog!$H$2:$H$378,"Open") | C26: =COUNTIFS(Backlog!$D$2:$D$378,$A26,Backlog!$H$2:$H$378,"Proposal") | D26: =COUNTIFS(Backlog!$D$2:$D$378,$A26,Backlog!$H$2:$H$378,"Needs testing") | E26: =COUNTIFS(Backlog!$D$2:$D$378,$A26,Backlog!$H$2:$H$378,"Disabled") | F26: =COUNTIFS(Backlog!$D$2:$D$378,$A26,Backlog!$H$2:$H$378,"Done") | G26: =SUM(B26:F26) | H26: =IF(G26=0,0,(B26+C26+D26)/G26)
A27: AI Overhaul | B27: =COUNTIFS(Backlog!$D$2:$D$378,$A27,Backlog!$H$2:$H$378,"Open") | C27: =COUNTIFS(Backlog!$D$2:$D$378,$A27,Backlog!$H$2:$H$378,"Proposal") | D27: =COUNTIFS(Backlog!$D$2:$D$378,$A27,Backlog!$H$2:$H$378,"Needs testing") | E27: =COUNTIFS(Backlog!$D$2:$D$378,$A27,Backlog!$H$2:$H$378,"Disabled") | F27: =COUNTIFS(Backlog!$D$2:$D$378,$A27,Backlog!$H$2:$H$378,"Done") | G27: =SUM(B27:F27) | H27: =IF(G27=0,0,(B27+C27+D27)/G27)
A28: Explosive Overhaul | B28: =COUNTIFS(Backlog!$D$2:$D$378,$A28,Backlog!$H$2:$H$378,"Open") | C28: =COUNTIFS(Backlog!$D$2:$D$378,$A28,Backlog!$H$2:$H$378,"Proposal") | D28: =COUNTIFS(Backlog!$D$2:$D$378,$A28,Backlog!$H$2:$H$378,"Needs testing") | E28: =COUNTIFS(Backlog!$D$2:$D$378,$A28,Backlog!$H$2:$H$378,"Disabled") | F28: =COUNTIFS(Backlog!$D$2:$D$378,$A28,Backlog!$H$2:$H$378,"Done") | G28: =SUM(B28:F28) | H28: =IF(G28=0,0,(B28+C28+D28)/G28)
A29: ToG Patch | B29: =COUNTIFS(Backlog!$D$2:$D$378,$A29,Backlog!$H$2:$H$378,"Open") | C29: =COUNTIFS(Backlog!$D$2:$D$378,$A29,Backlog!$H$2:$H$378,"Proposal") | D29: =COUNTIFS(Backlog!$D$2:$D$378,$A29,Backlog!$H$2:$H$378,"Needs testing") | E29: =COUNTIFS(Backlog!$D$2:$D$378,$A29,Backlog!$H$2:$H$378,"Disabled") | F29: =COUNTIFS(Backlog!$D$2:$D$378,$A29,Backlog!$H$2:$H$378,"Done") | G29: =SUM(B29:F29) | H29: =IF(G29=0,0,(B29+C29+D29)/G29)
A30: Total | B30: =SUM(B26:B29) | C30: =SUM(C26:C29) | D30: =SUM(D26:D29) | E30: =SUM(E26:E29) | F30: =SUM(F26:F29) | G30: =SUM(G26:G29) | H30: =IF(G30=0,0,(B30+C30+D30)/G30)
A32: By system
A33: System | B33: Open | C33: Proposal | D33: Needs testing | E33: Disabled | F33: Done | G33: Total | H33: Open %
A34: AI Behavior | B34: =COUNTIFS(Backlog!$E$2:$E$378,$A34,Backlog!$H$2:$H$378,"Open") | C34: =COUNTIFS(Backlog!$E$2:$E$378,$A34,Backlog!$H$2:$H$378,"Proposal") | D34: =COUNTIFS(Backlog!$E$2:$E$378,$A34,Backlog!$H$2:$H$378,"Needs testing") | E34: =COUNTIFS(Backlog!$E$2:$E$378,$A34,Backlog!$H$2:$H$378,"Disabled") | F34: =COUNTIFS(Backlog!$E$2:$E$378,$A34,Backlog!$H$2:$H$378,"Done") | G34: =SUM(B34:F34) | H34: =IF(G34=0,0,(B34+C34+D34)/G34)
A35: AP Economy | B35: =COUNTIFS(Backlog!$E$2:$E$378,$A35,Backlog!$H$2:$H$378,"Open") | C35: =COUNTIFS(Backlog!$E$2:$E$378,$A35,Backlog!$H$2:$H$378,"Proposal") | D35: =COUNTIFS(Backlog!$E$2:$E$378,$A35,Backlog!$H$2:$H$378,"Needs testing") | E35: =COUNTIFS(Backlog!$E$2:$E$378,$A35,Backlog!$H$2:$H$378,"Disabled") | F35: =COUNTIFS(Backlog!$E$2:$E$378,$A35,Backlog!$H$2:$H$378,"Done") | G35: =SUM(B35:F35) | H35: =IF(G35=0,0,(B35+C35+D35)/G35)
A36: Accuracy | B36: =COUNTIFS(Backlog!$E$2:$E$378,$A36,Backlog!$H$2:$H$378,"Open") | C36: =COUNTIFS(Backlog!$E$2:$E$378,$A36,Backlog!$H$2:$H$378,"Proposal") | D36: =COUNTIFS(Backlog!$E$2:$E$378,$A36,Backlog!$H$2:$H$378,"Needs testing") | E36: =COUNTIFS(Backlog!$E$2:$E$378,$A36,Backlog!$H$2:$H$378,"Disabled") | F36: =COUNTIFS(Backlog!$E$2:$E$378,$A36,Backlog!$H$2:$H$378,"Done") | G36: =SUM(B36:F36) | H36: =IF(G36=0,0,(B36+C36+D36)/G36)
A37: Animation | B37: =COUNTIFS(Backlog!$E$2:$E$378,$A37,Backlog!$H$2:$H$378,"Open") | C37: =COUNTIFS(Backlog!$E$2:$E$378,$A37,Backlog!$H$2:$H$378,"Proposal") | D37: =COUNTIFS(Backlog!$E$2:$E$378,$A37,Backlog!$H$2:$H$378,"Needs testing") | E37: =COUNTIFS(Backlog!$E$2:$E$378,$A37,Backlog!$H$2:$H$378,"Disabled") | F37: =COUNTIFS(Backlog!$E$2:$E$378,$A37,Backlog!$H$2:$H$378,"Done") | G37: =SUM(B37:F37) | H37: =IF(G37=0,0,(B37+C37+D37)/G37)
A38: Compatibility | B38: =COUNTIFS(Backlog!$E$2:$E$378,$A38,Backlog!$H$2:$H$378,"Open") | C38: =COUNTIFS(Backlog!$E$2:$E$378,$A38,Backlog!$H$2:$H$378,"Proposal") | D38: =COUNTIFS(Backlog!$E$2:$E$378,$A38,Backlog!$H$2:$H$378,"Needs testing") | E38: =COUNTIFS(Backlog!$E$2:$E$378,$A38,Backlog!$H$2:$H$378,"Disabled") | F38: =COUNTIFS(Backlog!$E$2:$E$378,$A38,Backlog!$H$2:$H$378,"Done") | G38: =SUM(B38:F38) | H38: =IF(G38=0,0,(B38+C38+D38)/G38)
A39: Components | B39: =COUNTIFS(Backlog!$E$2:$E$378,$A39,Backlog!$H$2:$H$378,"Open") | C39: =COUNTIFS(Backlog!$E$2:$E$378,$A39,Backlog!$H$2:$H$378,"Proposal") | D39: =COUNTIFS(Backlog!$E$2:$E$378,$A39,Backlog!$H$2:$H$378,"Needs testing") | E39: =COUNTIFS(Backlog!$E$2:$E$378,$A39,Backlog!$H$2:$H$378,"Disabled") | F39: =COUNTIFS(Backlog!$E$2:$E$378,$A39,Backlog!$H$2:$H$378,"Done") | G39: =SUM(B39:F39) | H39: =IF(G39=0,0,(B39+C39+D39)/G39)
A40: Explosives | B40: =COUNTIFS(Backlog!$E$2:$E$378,$A40,Backlog!$H$2:$H$378,"Open") | C40: =COUNTIFS(Backlog!$E$2:$E$378,$A40,Backlog!$H$2:$H$378,"Proposal") | D40: =COUNTIFS(Backlog!$E$2:$E$378,$A40,Backlog!$H$2:$H$378,"Needs testing") | E40: =COUNTIFS(Backlog!$E$2:$E$378,$A40,Backlog!$H$2:$H$378,"Disabled") | F40: =COUNTIFS(Backlog!$E$2:$E$378,$A40,Backlog!$H$2:$H$378,"Done") | G40: =SUM(B40:F40) | H40: =IF(G40=0,0,(B40+C40+D40)/G40)
A41: Fire Modes | B41: =COUNTIFS(Backlog!$E$2:$E$378,$A41,Backlog!$H$2:$H$378,"Open") | C41: =COUNTIFS(Backlog!$E$2:$E$378,$A41,Backlog!$H$2:$H$378,"Proposal") | D41: =COUNTIFS(Backlog!$E$2:$E$378,$A41,Backlog!$H$2:$H$378,"Needs testing") | E41: =COUNTIFS(Backlog!$E$2:$E$378,$A41,Backlog!$H$2:$H$378,"Disabled") | F41: =COUNTIFS(Backlog!$E$2:$E$378,$A41,Backlog!$H$2:$H$378,"Done") | G41: =SUM(B41:F41) | H41: =IF(G41=0,0,(B41+C41+D41)/G41)
A42: Loot & Economy | B42: =COUNTIFS(Backlog!$E$2:$E$378,$A42,Backlog!$H$2:$H$378,"Open") | C42: =COUNTIFS(Backlog!$E$2:$E$378,$A42,Backlog!$H$2:$H$378,"Proposal") | D42: =COUNTIFS(Backlog!$E$2:$E$378,$A42,Backlog!$H$2:$H$378,"Needs testing") | E42: =COUNTIFS(Backlog!$E$2:$E$378,$A42,Backlog!$H$2:$H$378,"Disabled") | F42: =COUNTIFS(Backlog!$E$2:$E$378,$A42,Backlog!$H$2:$H$378,"Done") | G42: =SUM(B42:F42) | H42: =IF(G42=0,0,(B42+C42+D42)/G42)
A43: Operations | B43: =COUNTIFS(Backlog!$E$2:$E$378,$A43,Backlog!$H$2:$H$378,"Open") | C43: =COUNTIFS(Backlog!$E$2:$E$378,$A43,Backlog!$H$2:$H$378,"Proposal") | D43: =COUNTIFS(Backlog!$E$2:$E$378,$A43,Backlog!$H$2:$H$378,"Needs testing") | E43: =COUNTIFS(Backlog!$E$2:$E$378,$A43,Backlog!$H$2:$H$378,"Disabled") | F43: =COUNTIFS(Backlog!$E$2:$E$378,$A43,Backlog!$H$2:$H$378,"Done") | G43: =SUM(B43:F43) | H43: =IF(G43=0,0,(B43+C43+D43)/G43)
...

Sheet Legend
A1: Field | B1: Value | C1: Meaning
A2: Priority | B2: P1 | C2: Must: blocks correctness/release, or flagged important/!!! in the original list
B3: P2 | C3: Should: core to the mod's direction
B4: P3 | C4: Could: nice to have, minor, or marked low priority
B5: P4 | C5: Won't now / wishlist: marked luxury or low priority
A6: Type | B6: Bug | C6: Behaves wrong vs. intended design
B7: Feature | C7: New mechanic, action, or behavior
B8: Balance | C8: Tuning numbers/curves of existing mechanics
B9: UX | C9: Information display / interaction clarity
B10: Text | C10: Description/hint wording only
B11: Investigation | C11: Unknown cause or open question; outcome is a finding
B12: QA | C12: Verify an existing system still works
B13: Refactor | C13: Code structure, no intended gameplay change
B14: Content | C14: Adding/removing/renaming presets (components, calibers)
B15: Art/Content | C15: Icons, models
B16: Tooling/Docs | C16: Spreadsheets, debug overlays, internal docs
A17: Status | B17: Open | C17: Not started / in progress
B18: Proposal | C18: Idea marked '?' in the original; needs a design decision first
B19: Needs testing | C19: Implemented but flagged for more testing
B20: Disabled | C20: Implemented but turned off
B21: Done | C21: Checked in the original list
A22: Effort | B22: XS-XL | C22: Yellow cells: left blank for you to fill
A23: Parent | B23: T-xxx | C23: Sub-task of that ID (indented with ↳ in Task)
A24: Note | C24: Priority, Type and System were assigned by Claude from the wording; treat as a first pass.
